<?xml version="1.0" ?>

<robot name="mrm" xmlns:xacro="http://www.ros.org/wiki/xacro">
    

  <link name="base_link">
      <visual>
        <origin rpy="0 0 0" xyz="0 0 0.05" />
        <geometry>
          <box size="1 1 0.1" />
        </geometry>
      </visual>
      <gravity>0</gravity>
    </link>

    <joint name="base_link__link_01" type="revolute">
      <axis xyz="0 1 0" />
      <limit effort="1000.0" lower="-3.14" upper="3.14" velocity="0.5" />
      <origin rpy="0 0 0.1" xyz="0 0 0.1" />
      <parent link="base_link" />
      <child link="link_01" />
    </joint>


    <link name="link_01">
      <visual>
        <origin rpy="0 0 0" xyz="0 0 1.5" />
        <geometry>
          <box size="0.1 0.1 3" />
        </geometry>
      </visual>
      <gravity>0</gravity>
    </link>

<!--               
  <m_joint name="${link_01_name}__${link_02_name}" type="revolute"
           axis_xyz="0 1 0"
           origin_rpy="0 0 0.1" origin_xyz="0 0 0.1"
           parent="${link_00_name}" child="${link_02_name}" />
           
  <m_link_cylinder name="${link_02_name}"
              origin_rpy="0 0 0" origin_xyz="0 0 0.1"
              mass="57.906"
              ixx="12.679" ixy="0" ixz="0"
              iyy="12.679" iyz="0"
              izz="0.651"
              radius="0.15" length="0.8" />
              
  <m_joint name="${link_02_name}__${link_03_name}" type="revolute"
           axis_xyz="0 1 0"
           origin_rpy="0 0 0" origin_xyz="0 0 0.9"
           parent="${link_02_name}" child="${link_03_name}" />
           
  <m_link_cylinder name="${link_03_name}"
              origin_rpy="0 0 0" origin_xyz="0 0 0.4"
              mass="57.906"
              ixx="12.679" ixy="0" ixz="0"
              iyy="12.679" iyz="0"
              izz="0.651"
              radius="0.15" length="0.8" />
  END - Robot description -->
  
</robot>
